<?xml version="1.0" ?>
<!-- =================================================================================== -->
<!-- |    This document was autogenerated by xacro from jackal.urdf.xacro              | -->
<!-- |    EDITING THIS FILE BY HAND IS NOT RECOMMENDED                                 | -->
<!-- =================================================================================== -->
<robot name="jackal">
  <!-- material color parameters -->
  <material name="dark_grey">
    <color rgba="0.2 0.2 0.2 1.0"/>
  </material>
  <material name="light_grey">
    <color rgba="0.7 0.7 0.7 1.0"/>
  </material>
  <!-- hokuyo 3D model color -->
  <material name="yellow">
    <color rgba="0.8 0.8 0.0 1.0"/>
  </material>
  <material name="cyan">
    <color rgba="0 1.0 1.0 1.0"/>
  </material>
  <!-- velodyne 3D model color -->
  <material name="white">
    <color rgba="1.0 1.0 1.0 1.0"/>
  </material>
  <material name="violet">
    <color rgba="0.7 0.3 1.0 1.0"/>
  </material>
  <!-- sensor board 3D model color -->
  <material name="black">
    <color rgba="0.15 0.15 0.15 1.0"/>
  </material>
  <!-- xsens imu 3D model color -->
  <material name="orange">
    <color rgba="1.0 0.5 0.2 1"/>
  </material>
  <link name="front_left_wheel_link">
    <visual>
      <origin rpy="1.5707963267948966 0 0" xyz="0 0 0"/>
      <geometry>
        <mesh filename="package://star_jackal_mapper_description/meshes/jackal-wheel.stl"/>
      </geometry>
      <material name="black"/>
    </visual>
    <collision>
      <origin rpy="1.5707963267948966 0 0" xyz="0 0 0"/>
      <geometry>
        <cylinder length="0.04" radius="0.098"/>
      </geometry>
    </collision>
    <inertial>
      <origin rpy="0 0 0" xyz="0 0 0"/>
      <mass value="0.477"/>
      <inertia ixx="0.0013" ixy="0" ixz="0" iyy="0.0024" iyz="0" izz="0.0013"/>
    </inertial>
  </link>
  <gazebo reference="front_left_wheel_link">
    <material>Gazebo/DarkGrey</material>
  </gazebo>
  <joint name="front_left_wheel" type="continuous">
    <parent link="chassis_link"/>
    <child link="front_left_wheel_link"/>
    <origin rpy="0 0 0" xyz="0.131 0.187795 0.0345"/>
    <axis xyz="0 1 0"/>
  </joint>
  <!-- In reality, Jackal has only two motors, one per side. However, it's more
         straightforward for Gazebo to simulate as if there's an actuator per wheel. -->
  <transmission name="front_left_wheel_trans">
    <type>transmission_interface/SimpleTransmission</type>
    <joint name="front_left_wheel">
      <hardwareInterface>VelocityJointInterface</hardwareInterface>
    </joint>
    <actuator name="front_left_actuator">
      <mechanicalReduction>1</mechanicalReduction>
    </actuator>
  </transmission>
  <link name="front_right_wheel_link">
    <visual>
      <origin rpy="1.5707963267948966 0 0" xyz="0 0 0"/>
      <geometry>
        <mesh filename="package://star_jackal_mapper_description/meshes/jackal-wheel.stl"/>
      </geometry>
      <material name="black"/>
    </visual>
    <collision>
      <origin rpy="1.5707963267948966 0 0" xyz="0 0 0"/>
      <geometry>
        <cylinder length="0.04" radius="0.098"/>
      </geometry>
    </collision>
    <inertial>
      <origin rpy="0 0 0" xyz="0 0 0"/>
      <mass value="0.477"/>
      <inertia ixx="0.0013" ixy="0" ixz="0" iyy="0.0024" iyz="0" izz="0.0013"/>
    </inertial>
  </link>
  <gazebo reference="front_right_wheel_link">
    <material>Gazebo/DarkGrey</material>
  </gazebo>
  <joint name="front_right_wheel" type="continuous">
    <parent link="chassis_link"/>
    <child link="front_right_wheel_link"/>
    <origin rpy="0 0 0" xyz="0.131 -0.187795 0.0345"/>
    <axis xyz="0 1 0"/>
  </joint>
  <!-- In reality, Jackal has only two motors, one per side. However, it's more
         straightforward for Gazebo to simulate as if there's an actuator per wheel. -->
  <transmission name="front_right_wheel_trans">
    <type>transmission_interface/SimpleTransmission</type>
    <joint name="front_right_wheel">
      <hardwareInterface>VelocityJointInterface</hardwareInterface>
    </joint>
    <actuator name="front_right_actuator">
      <mechanicalReduction>1</mechanicalReduction>
    </actuator>
  </transmission>
  <link name="rear_left_wheel_link">
    <visual>
      <origin rpy="1.5707963267948966 0 0" xyz="0 0 0"/>
      <geometry>
        <mesh filename="package://star_jackal_mapper_description/meshes/jackal-wheel.stl"/>
      </geometry>
      <material name="black"/>
    </visual>
    <collision>
      <origin rpy="1.5707963267948966 0 0" xyz="0 0 0"/>
      <geometry>
        <cylinder length="0.04" radius="0.098"/>
      </geometry>
    </collision>
    <inertial>
      <origin rpy="0 0 0" xyz="0 0 0"/>
      <mass value="0.477"/>
      <inertia ixx="0.0013" ixy="0" ixz="0" iyy="0.0024" iyz="0" izz="0.0013"/>
    </inertial>
  </link>
  <gazebo reference="rear_left_wheel_link">
    <material>Gazebo/DarkGrey</material>
  </gazebo>
  <joint name="rear_left_wheel" type="continuous">
    <parent link="chassis_link"/>
    <child link="rear_left_wheel_link"/>
    <origin rpy="0 0 0" xyz="-0.131 0.187795 0.0345"/>
    <axis xyz="0 1 0"/>
  </joint>
  <!-- In reality, Jackal has only two motors, one per side. However, it's more
         straightforward for Gazebo to simulate as if there's an actuator per wheel. -->
  <transmission name="rear_left_wheel_trans">
    <type>transmission_interface/SimpleTransmission</type>
    <joint name="rear_left_wheel">
      <hardwareInterface>VelocityJointInterface</hardwareInterface>
    </joint>
    <actuator name="rear_left_actuator">
      <mechanicalReduction>1</mechanicalReduction>
    </actuator>
  </transmission>
  <link name="rear_right_wheel_link">
    <visual>
      <origin rpy="1.5707963267948966 0 0" xyz="0 0 0"/>
      <geometry>
        <mesh filename="package://star_jackal_mapper_description/meshes/jackal-wheel.stl"/>
      </geometry>
      <material name="black"/>
    </visual>
    <collision>
      <origin rpy="1.5707963267948966 0 0" xyz="0 0 0"/>
      <geometry>
        <cylinder length="0.04" radius="0.098"/>
      </geometry>
    </collision>
    <inertial>
      <origin rpy="0 0 0" xyz="0 0 0"/>
      <mass value="0.477"/>
      <inertia ixx="0.0013" ixy="0" ixz="0" iyy="0.0024" iyz="0" izz="0.0013"/>
    </inertial>
  </link>
  <gazebo reference="rear_right_wheel_link">
    <material>Gazebo/DarkGrey</material>
  </gazebo>
  <joint name="rear_right_wheel" type="continuous">
    <parent link="chassis_link"/>
    <child link="rear_right_wheel_link"/>
    <origin rpy="0 0 0" xyz="-0.131 -0.187795 0.0345"/>
    <axis xyz="0 1 0"/>
  </joint>
  <!-- In reality, Jackal has only two motors, one per side. However, it's more
         straightforward for Gazebo to simulate as if there's an actuator per wheel. -->
  <transmission name="rear_right_wheel_trans">
    <type>transmission_interface/SimpleTransmission</type>
    <joint name="rear_right_wheel">
      <hardwareInterface>VelocityJointInterface</hardwareInterface>
    </joint>
    <actuator name="rear_right_actuator">
      <mechanicalReduction>1</mechanicalReduction>
    </actuator>
  </transmission>
  <link name="base_link"/>
  <!-- robot ground -->
  <link name="foot_link"/>
  <joint name="foot_link_joint" type="fixed">
    <origin rpy="0 0 0" xyz="0 0 -0.0655"/>
    <parent link="base_link"/>
    <child link="foot_link"/>
  </joint>
  <joint name="base_link_joint" type="fixed">
    <origin rpy="0 0 0" xyz="0 0 0"/>
    <parent link="base_link"/>
    <child link="chassis_link"/>
  </joint>
  <link name="chassis_link">
    <visual>
      <origin rpy="1.5707963267948966 0 1.5707963267948966" xyz="0 0 -0.0655"/>
      <geometry>
        <mesh filename="package://star_jackal_mapper_description/meshes/jackal-base.stl"/>
      </geometry>
      <material name="dark_grey"/>
    </visual>
    <collision>
      <origin xyz="0 0 0.092"/>
      <geometry>
        <box size="0.42 0.31 0.184"/>
      </geometry>
    </collision>
    <inertial>
      <!-- Center of mass -->
      <origin rpy="0 0 0" xyz="0.012  0.002 0.067"/>
      <mass value="16.523"/>
      <!-- Moments of inertia: ( chassis without wheels ) -->
      <inertia ixx="0.3136" ixy="-0.0008" ixz="0.0164" iyy="0.3922" iyz="-0.0009" izz="0.4485"/>
    </inertial>
  </link>
  <link name="fenders_link">
    <visual>
      <origin rpy="1.5707963267948966 0 1.5707963267948966" xyz="0 0 -0.0655"/>
      <geometry>
        <mesh filename="package://star_jackal_mapper_description/meshes/jackal-fenders.stl"/>
      </geometry>
      <material name="yellow"/>
    </visual>
  </link>
  <joint name="fenders_joint" type="fixed">
    <parent link="chassis_link"/>
    <child link="fenders_link"/>
  </joint>
  <!-- TODO: Make this internal_imu_link or something, and use a mixed-in xacro
       to supply the joint between it and imu_link. This is important so that imu_link
       always points to the "active" IMU. When an upgrade IMU is connected, the
       internal_imu_link should remain, but imu_link should point to the upgrade one. -->
  <link name="imu_link">
    <inertial>
      <mass value="0.001"/>
      <origin rpy="0 0 0" xyz="0 0 0"/>
      <inertia ixx="1e-09" ixy="0.0" ixz="0.0" iyy="1e-09" iyz="0.0" izz="1e-09"/>
    </inertial>
  </link>
  <joint name="imu_joint" type="fixed">
    <parent link="chassis_link"/>
    <child link="imu_link"/>
  </joint>
  <!-- TODO: Same note as applies to imu_link -->
  <link name="navsat_link">
    <visual>
      <geometry>
        <cylinder length="0.016" radius="0.026"/>
      </geometry>
      <origin xyz="0 0 0.008"/>
      <material name="black"/>
    </visual>
  </link>
  <joint name="navsat_joint" type="fixed">
    <parent link="chassis_link"/>
    <child link="navsat_link"/>
    <origin xyz="-0.180 0.126 0.1815"/>
  </joint>
  <!--
    As you add to this URDF, please be aware that both the robot and
    simulation include it. You must retain compatibility with all of
    the following launch files:

    jackal_viz/launch/view_model.launch
    jackal_gazebo/launch/jackal_world.launch
    jackal_base/launch/base.launch
  -->
  <!--============-->
  <!-- board link -->
  <!--============-->
  <link name="board_link">
    <visual>
      <geometry>
        <box size="0.47 0.3 0.008"/>
      </geometry>
      <origin xyz="0 0 0"/>
      <material name="black"/>
    </visual>
  </link>
  <!-- board_joint -->
  <joint name="board_joint" type="fixed">
    <parent link="chassis_link"/>
    <child link="board_link"/>
    <origin rpy="0 0 0" xyz="0 0 0.238"/>
  </joint>
  <link name="tracking_system">
    <visual>
      <geometry>
        <box size="0.02 0.02 0.02"/>
      </geometry>
    </visual>
  </link>
  <joint name="tracking_systen_link" type="fixed">
    <parent link="board_link"/>
    <child link="tracking_system"/>
    <origin rpy="0 0 0" xyz="-0.05 0 0.02 "/>
  </joint>
  <!--================-->
  <!-- xsens_imu_link -->
  <!--================-->
  <MTI-30 name="xsens_imu" parent="board_link">
    <origin rpy="0 3.141592653589793 1.5707963267948966" xyz="0 0 0"/>
  </MTI-30>
  <!--<link name="xsens_imu_link">-->
  <!--<visual>-->
  <!--<geometry>-->
  <!--<box size="0.0565 0.0414 0.0234" />-->
  <!--</geometry>-->
  <!--<origin xyz="0 0 0" />-->
  <!--<material name="orange" />-->
  <!--</visual>-->
  <!--</link>-->
  <!--&lt;!&ndash; xsens_imu_joint &ndash;&gt;-->
  <!--<joint name="xsens_imu_joint" type="fixed">-->
  <!--<parent link="board_link" />-->
  <!--<child  link="xsens_imu_link" />-->
  <!--<origin xyz="0 -0.0164 -0.0121" rpy="0 ${PI} 0" />-->
  <!--</joint>-->
  <!--========================-->
  <!-- horizontal_hokuyo_link -->
  <!--========================-->
  <!-- from front_sensor_board to front_board aluminum_support length -->
  <!--<xacro:property name="horizontal_laser_x_offset"   value="0.013"  />-->
  <!--&lt;!&ndash; hokuyo width from offical datasheet of ust-10lx &ndash;&gt;-->
  <!--&lt;!&ndash;<xacro:property name="hokuyo_width"                value="0.05"   />&ndash;&gt;-->
  <!--&lt;!&ndash; hokuyo model z offset check xyz = (0 0 0) origin &ndash;&gt;-->
  <!--<xacro:property name="horizontal_laser_z_offset"   value="0.001"  />-->
  <!--==================================-->
  <!-- proof of horizontal hokuyo laser -->
  <!--<link name="horizontal_laser_offset_link">-->
  <!--<visual>-->
  <!--<geometry>-->
  <!--<box size="${horizontal_laser_x_offset} ${sensor_board_width} ${sensor_board_height}"     />-->
  <!--</geometry>-->
  <!--<origin xyz="0 0 0"    />-->
  <!--<material name="white" />-->
  <!--</visual>-->
  <!--</link>-->
  <!-- board_joint -->
  <!--<joint name="horizontal_laser_offset_joint" type="fixed">-->
  <!--<parent link="board_link" />-->
  <!--<child  link="horizontal_laser_offset_link"    />-->
  <!--<origin xyz ="${(sensor_board_length-horizontal_laser_x_offset)*0.5} 0 ${sensor_board_height}" />-->
  <!--</joint>-->
  <!--================================-->
  <!-- UST-10LX -->
  <!--<UST-10LX name="horizontal_hokuyo" parent="board_link" color="cyan" >-->
  <!--<origin xyz ="${sensor_board_length*0.5-horizontal_laser_x_offset-hokuyo_width*0.5} 0 ${aluminum_support_height+sensor_board_height+horizontal_laser_z_offset}" rpy="0 0 0" />-->
  <!--</UST-10LX>-->
  <!--======================-->
  <!-- vertical_hokuyo_link -->
  <!--======================-->
  <!--================================-->
  <!-- proof of vertical hokuyo laser -->
  <!--<link name="vertical_laser_offset_link">-->
  <!--<visual>-->
  <!--<geometry>-->
  <!--<box size="${vertical_laser_x_offset} ${sensor_board_width} ${sensor_board_height*2}" />-->
  <!--</geometry>-->
  <!--<origin xyz="0 0 0"    />-->
  <!--<material name="white" />-->
  <!--</visual>-->
  <!--</link>-->
  <!--&lt;!&ndash; board_joint &ndash;&gt;-->
  <!--<joint name="vertical_laser_offset_joint" type="fixed">-->
  <!--<parent link="board_link" />-->
  <!--<child  link="vertical_laser_offset_link"    />-->
  <!--<origin xyz ="${(sensor_board_length-vertical_laser_x_offset)*0.5} 0 0" />-->
  <!--</joint>-->
  <!--================================-->
  <!-- a virtual link to compensate the roll of vertical hokuyo, dead-lock yrp program -->
  <link name="virtual_link"/>
  <joint name="virtual_joint" type="fixed">
    <parent link="board_link"/>
    <child link="virtual_link"/>
    <origin rpy="-0.02617993877991494 0 0" xyz="0 0 0"/>
  </joint>
  <!--================================-->
  <!--<UST-10LX name="vertical_hokuyo" parent="virtual_link" color="yellow" >-->
  <!--<origin xyz="${hokuyo_height+sensor_board_height} 0 ${vertical_laser_height+0.01}" rpy="0 ${-PI/2} ${PI}" />-->
  <!--</UST-10LX>-->
  <!--======================-->
  <!--        cameras       -->
  <!--======================-->
  <GS3 name="camera_left_front" parent="board_link">
    <origin rpy="1.5707963267948966 3.141592653589793 3.141592653589793" xyz="0.2138 0.19105 -0.018"/>
  </GS3>
  <GS3 name="camera_right_front" parent="board_link">
    <origin rpy="1.5707963267948966 3.141592653589793 0" xyz="0.21 -0.19 -0.018"/>
  </GS3>
  <GS3 name="camera_left_back" parent="board_link">
    <origin rpy="1.5707963267948966 3.141592653589793 3.141592653589793" xyz="-0.21 0.19 -0.018"/>
  </GS3>
  <GS3 name="camera_right_back" parent="board_link">
    <origin rpy="1.5707963267948966 3.141592653589793 0" xyz="-0.21 -0.19 -0.018"/>
  </GS3>
  <GS3 name="camera_up_l" parent="board_link">
    <origin rpy="0 0 0" xyz="0.11 0.14 0.23"/>
  </GS3>
  <GS3 name="camera_up_r" parent="board_link">
    <origin rpy="0 0 3.141592653589793" xyz="0.11 -0.14 0.23"/>
  </GS3>
  <GS3 name="camera_front_l" parent="board_link">
    <origin rpy="1.5707963267948966 0 1.5707963267948966" xyz="0.18 0.07 0.25"/>
  </GS3>
  <GS3 name="camera_front_r" parent="board_link">
    <origin rpy="1.5707963267948966 0 1.5707963267948966" xyz="0.18 -0.07 0.25"/>
  </GS3>
  <GS3 name="camera_back" parent="board_link">
    <origin rpy="1.5707963267948966 3.141592653589793 4.71238898038469" xyz="-0.01 0 0.20"/>
  </GS3>
  <!--<GS3 name="front_right_camera" parent="board_link" >-->
  <!--<origin xyz="${(chassis_length+0.06)*0.5-0.05+0.027} ${-chassis_width*0.5-0.021} ${0.0145+0.004}" rpy="${PI/2} 0 ${PI/2}" />-->
  <!--</GS3>-->
  <!--<link name="front_left_camera_link">-->
  <!--<visual>-->
  <!--<geometry>-->
  <!--<box size="0.044 0.029 0.0954" />-->
  <!--</geometry>-->
  <!--<origin xyz="0 0 -0.047" />-->
  <!--<material name="black" />-->
  <!--</visual>-->
  <!--</link>-->
  <!--<joint name="front_left_camera_joint" type="fixed">-->
  <!--<parent link="board_link" />-->
  <!--<child link="front_left_camera_link" />-->
  <!--<origin xyz="0.23964 0.12564 0.0185" rpy="${-PI/2} 0 ${-PI/2}" />-->
  <!--</joint>-->
  <!--<link name="front_right_camera_link">-->
  <!--<visual>-->
  <!--<geometry>-->
  <!--<box size="0.044 0.029 0.0954" />-->
  <!--</geometry>-->
  <!--<origin xyz="0 0 -0.047" />-->
  <!--<material name="black" />-->
  <!--</visual>-->
  <!--</link>-->
  <!--<joint name="front_right_camera_joint" type="fixed">-->
  <!--<parent link="board_link" />-->
  <!--<child link="front_right_camera_link" />-->
  <!--<origin xyz="0.23912 -0.13633 0.0185" rpy="${-PI/2} 0 ${-PI/2}" />-->
  <!--</joint>-->
  <!--<link name="up_camera_link">-->
  <!--<visual>-->
  <!--<geometry>-->
  <!--<box size="0.044 0.029 0.096" />-->
  <!--</geometry>-->
  <!--<origin xyz="0 0 -0.048" />-->
  <!--<material name="black" />-->
  <!--</visual>-->
  <!--</link>-->
  <!--<joint name="up_camera_joint" type="fixed">-->
  <!--<parent link="board_link" />-->
  <!--<child link="up_camera_link" />-->
  <!--<origin xyz="-0.02 0 0.25" rpy="0 0 ${-PI/2}" />-->
  <!--</joint>-->
  <!--=========-->
  <!-- HDL-32E -->
  <!--=========-->
  <!--<xacro:property name="velodyne_offset_length"   value="0.2" />-->
  <!--<xacro:property name="left_velodyne_x_offset"   value="0.211" />-->
  <!--<link name="velodyne_offset_link">-->
  <!--<visual>-->
  <!--<geometry>-->
  <!--<box size="${velodyne_offset_length} ${sensor_board_width} ${sensor_board_height}"     />-->
  <!--</geometry>-->
  <!--<origin xyz="0 0 0"    />-->
  <!--<material name="white" />-->
  <!--</visual>-->
  <!--</link>-->
  <!--&lt;!&ndash; velodyne_offset_joint &ndash;&gt;-->
  <!--<joint name="velodyne_offset_joint" type="fixed">-->
  <!--<parent link="board_link" />-->
  <!--<child  link="velodyne_offset_link" />-->
  <!--<origin xyz ="${-(sensor_board_length-velodyne_offset_length)*0.5} 0 ${sensor_board_height}" />-->
  <!--</joint>-->
  <!-- left_velodyne -->
  <HDL-32E color="white" name="vertical_velodyne" parent="board_link">
    <!--<origin xyz="-0.063 0.085 0.216" rpy="${PI/4-3*PI/180} ${PI/4+1.5*PI/180} ${-PI-2.4*PI/180}"/>-->
    <!--<origin xyz="-0.15 0.20 0.29" rpy="${PI/4+1*PI/180} ${PI/4+4.2*PI/180} ${-PI-2*PI/180}"/>-->
    <origin rpy="0 0 -1.5707963267948966" xyz="0.12 0.01 0.33"/>
  </HDL-32E>
  <!-- right_velodyne -->
  <HDL-32E color="white" name="horizontal_velodyne" parent="board_link">
    <!--<origin xyz="-0.063 -0.085 0.216" rpy="${PI/4-1*PI/180} ${-PI/4-6*PI/180} ${0-1*PI/180}"/>-->
    <origin rpy="1.5707963267948966 0 1.5707963267948966" xyz="0.30 0.01 0.11"/>
  </HDL-32E>
</robot>

